conformant = "Unsupported"
notes = """
Does not support TypeVarTuple.
"""
output = """
File "generics_typevartuple_callable.py", line 10, in <module>: typing.TypeVarTuple not supported yet [not-supported-yet]
File "generics_typevartuple_callable.py", line 12, in <module>: Function TypeVarTuple.__init__ expects 1 arg(s), got 2 [wrong-arg-count]
File "generics_typevartuple_callable.py", line 17, in Process: Invalid type annotation '<instance of Tuple[nothing, ...]>'  [invalid-annotation]
File "generics_typevartuple_callable.py", line 17, in Process: Invalid type annotation '<instance of List[nothing]>'  [invalid-annotation]
File "generics_typevartuple_callable.py", line 25, in <module>: Function Process.__init__ was called with the wrong arguments [wrong-arg-types]
File "generics_typevartuple_callable.py", line 26, in <module>: Function Process.__init__ was called with the wrong arguments [wrong-arg-types]
File "generics_typevartuple_callable.py", line 29, in <module>: Invalid type annotation '<instance of Tuple[nothing, ...]>'  [invalid-annotation]
File "generics_typevartuple_callable.py", line 29, in <module>: Invalid type annotation '<instance of Tuple[TypeVar, ...]>'  [invalid-annotation]
File "generics_typevartuple_callable.py", line 29, in <module>: Invalid type annotation '<instance of List[Type[int]]>'  [invalid-annotation]
File "generics_typevartuple_callable.py", line 30, in func2: bad return type [bad-return-type]
Called from (traceback):
  line 42, in current file
File "generics_typevartuple_callable.py", line 34, in callback1: bad return type [bad-return-type]
File "generics_typevartuple_callable.py", line 38, in callback2: bad return type [bad-return-type]
File "generics_typevartuple_callable.py", line 41, in <module>: Function func2 was called with the wrong arguments [wrong-arg-types]
File "generics_typevartuple_callable.py", line 41, in <module>: Any [assert-type]
File "generics_typevartuple_callable.py", line 42, in <module>: Tuple[Any] [assert-type]
File "generics_typevartuple_callable.py", line 45, in <module>: Missing parameter 'self' in call to function tuple.__iter__ [missing-parameter]
File "generics_typevartuple_callable.py", line 45, in <module>: Invalid type annotation '<instance of Tuple[Type[int], ...]>'  [invalid-annotation]
File "generics_typevartuple_callable.py", line 45, in <module>: Invalid type annotation '<instance of Tuple[TypeVar, ...]>'  [invalid-annotation]
File "generics_typevartuple_callable.py", line 46, in func3: bad return type [bad-return-type]
Called from (traceback):
  line 49, in current file
File "generics_typevartuple_callable.py", line 49, in <module>: Tuple[Any] [assert-type]
"""
conformance_automated = "Fail"
errors_diff = """
Line 10: Unexpected errors ['File "generics_typevartuple_callable.py", line 10, in <module>: typing.TypeVarTuple not supported yet [not-supported-yet]']
Line 12: Unexpected errors ['File "generics_typevartuple_callable.py", line 12, in <module>: Function TypeVarTuple.__init__ expects 1 arg(s), got 2 [wrong-arg-count]']
Line 17: Unexpected errors ['File "generics_typevartuple_callable.py", line 17, in Process: Invalid type annotation \\'<instance of Tuple[nothing, ...]>\\'  [invalid-annotation]', 'File "generics_typevartuple_callable.py", line 17, in Process: Invalid type annotation \\'<instance of List[nothing]>\\'  [invalid-annotation]']
Line 25: Unexpected errors ['File "generics_typevartuple_callable.py", line 25, in <module>: Function Process.__init__ was called with the wrong arguments [wrong-arg-types]']
Line 29: Unexpected errors ['File "generics_typevartuple_callable.py", line 29, in <module>: Invalid type annotation \\'<instance of Tuple[nothing, ...]>\\'  [invalid-annotation]', 'File "generics_typevartuple_callable.py", line 29, in <module>: Invalid type annotation \\'<instance of Tuple[TypeVar, ...]>\\'  [invalid-annotation]', 'File "generics_typevartuple_callable.py", line 29, in <module>: Invalid type annotation \\'<instance of List[Type[int]]>\\'  [invalid-annotation]']
Line 30: Unexpected errors ['File "generics_typevartuple_callable.py", line 30, in func2: bad return type [bad-return-type]']
Line 34: Unexpected errors ['File "generics_typevartuple_callable.py", line 34, in callback1: bad return type [bad-return-type]']
Line 38: Unexpected errors ['File "generics_typevartuple_callable.py", line 38, in callback2: bad return type [bad-return-type]']
Line 41: Unexpected errors ['File "generics_typevartuple_callable.py", line 41, in <module>: Function func2 was called with the wrong arguments [wrong-arg-types]', 'File "generics_typevartuple_callable.py", line 41, in <module>: Any [assert-type]']
Line 42: Unexpected errors ['File "generics_typevartuple_callable.py", line 42, in <module>: Tuple[Any] [assert-type]']
Line 45: Unexpected errors ['File "generics_typevartuple_callable.py", line 45, in <module>: Missing parameter \\'self\\' in call to function tuple.__iter__ [missing-parameter]', 'File "generics_typevartuple_callable.py", line 45, in <module>: Invalid type annotation \\'<instance of Tuple[Type[int], ...]>\\'  [invalid-annotation]', 'File "generics_typevartuple_callable.py", line 45, in <module>: Invalid type annotation \\'<instance of Tuple[TypeVar, ...]>\\'  [invalid-annotation]']
Line 46: Unexpected errors ['File "generics_typevartuple_callable.py", line 46, in func3: bad return type [bad-return-type]']
Line 49: Unexpected errors ['File "generics_typevartuple_callable.py", line 49, in <module>: Tuple[Any] [assert-type]']
"""
