conformant = "Unsupported"
notes = """
Does not understand `Self` type.
"""
output = """
File "generics_self_advanced.py", line 12, in prop1: bad return type [bad-return-type]
Called from (traceback):
  line 19, in current file
File "generics_self_advanced.py", line 12, in prop1: bad return type [bad-return-type]
Called from (traceback):
  line 18, in current file
File "generics_self_advanced.py", line 19, in <module>: ParentA [assert-type]
File "generics_self_advanced.py", line 29, in method1: bad return type [bad-return-type]
Called from (traceback):
  line 38, in method2
File "generics_self_advanced.py", line 29, in method1: bad return type [bad-return-type]
File "generics_self_advanced.py", line 35, in method2: ChildB [assert-type]
File "generics_self_advanced.py", line 36, in method2: List[ChildB] [assert-type]
File "generics_self_advanced.py", line 37, in method2: ChildB [assert-type]
File "generics_self_advanced.py", line 38, in method2: ChildB [assert-type]
File "generics_self_advanced.py", line 42, in method3: Type[ChildB] [assert-type]
File "generics_self_advanced.py", line 43, in method3: List[ChildB] [assert-type]
File "generics_self_advanced.py", line 44, in method3: ChildB [assert-type]
File "generics_self_advanced.py", line 45, in method3: ChildB [assert-type]
"""
conformance_automated = "Fail"
errors_diff = """
Line 12: Unexpected errors ['File "generics_self_advanced.py", line 12, in prop1: bad return type [bad-return-type]', 'File "generics_self_advanced.py", line 12, in prop1: bad return type [bad-return-type]']
Line 19: Unexpected errors ['File "generics_self_advanced.py", line 19, in <module>: ParentA [assert-type]']
Line 29: Unexpected errors ['File "generics_self_advanced.py", line 29, in method1: bad return type [bad-return-type]', 'File "generics_self_advanced.py", line 29, in method1: bad return type [bad-return-type]']
Line 35: Unexpected errors ['File "generics_self_advanced.py", line 35, in method2: ChildB [assert-type]']
Line 36: Unexpected errors ['File "generics_self_advanced.py", line 36, in method2: List[ChildB] [assert-type]']
Line 37: Unexpected errors ['File "generics_self_advanced.py", line 37, in method2: ChildB [assert-type]']
Line 38: Unexpected errors ['File "generics_self_advanced.py", line 38, in method2: ChildB [assert-type]']
Line 42: Unexpected errors ['File "generics_self_advanced.py", line 42, in method3: Type[ChildB] [assert-type]']
Line 43: Unexpected errors ['File "generics_self_advanced.py", line 43, in method3: List[ChildB] [assert-type]']
Line 44: Unexpected errors ['File "generics_self_advanced.py", line 44, in method3: ChildB [assert-type]']
Line 45: Unexpected errors ['File "generics_self_advanced.py", line 45, in method3: ChildB [assert-type]']
"""
